<sdf version='1.9'>
  <world name='world_demo'>
    <physics name='1ms' type='ignored'>
      <max_step_size>0.01</max_step_size>
      <real_time_factor>1</real_time_factor>
      <real_time_update_rate>1000</real_time_update_rate>
    </physics>
    <plugin name='ignition::gazebo::systems::Physics' filename='libignition-gazebo-physics-system.so'/>
    <plugin name='ignition::gazebo::systems::UserCommands' filename='libignition-gazebo-user-commands-system.so'/>
    <plugin name='ignition::gazebo::systems::SceneBroadcaster' filename='libignition-gazebo-scene-broadcaster-system.so'/>
    <plugin name='ignition::gazebo::systems::Imu' filename='ignition-gazebo-imu-system'/>
    <plugin name='ignition::gazebo::systems::Sensors' filename='ignition-gazebo-sensors-system'>
      <render_engine>ogre2</render_engine>
    </plugin>
    <scene>
      <ambient>1 1 1 1</ambient>
      <background>0.3 0.7 0.9 1</background>
      <shadows>false</shadows>
      <grid>true</grid>
    </scene>
    <gravity>0 0 -9.8</gravity>
    <magnetic_field>6e-06 2.3e-05 -4.2e-05</magnetic_field>
    <atmosphere type='adiabatic'/>
    <model name='ground_plane'>
      <static>true</static>
      <link name='link'>
        <collision name='collision'>
          <geometry>
            <plane>
              <normal>0 0 1</normal>
              <size>1 1</size>
            </plane>
          </geometry>
          <surface>
            <friction>
              <ode/>
            </friction>
            <bounce/>
            <contact/>
          </surface>
        </collision>
        <pose>0 0 0 0 -0 0</pose>
        <inertial>
          <pose>0 0 0 0 -0 0</pose>
          <mass>1</mass>
          <inertia>
            <ixx>1</ixx>
            <ixy>0</ixy>
            <ixz>0</ixz>
            <iyy>1</iyy>
            <iyz>0</iyz>
            <izz>1</izz>
          </inertia>
        </inertial>
        <enable_wind>false</enable_wind>
      </link>
      <pose>0 0 0 0 -0 0</pose>
      <self_collide>false</self_collide>
    </model>
    <model name='Depot'>
      <static>false</static>
      <link name='main'>
        <collision name='collision'>
          <pose>0 0 0 0 0 0</pose>
          <geometry>
            <plane>
              <normal>0 0 1</normal>
              <size>100 100</size>
            </plane>
          </geometry>
          <surface>
            <friction>
              <ode/>
            </friction>
            <bounce/>
            <contact/>
          </surface>
        </collision>
        <visual name='ROOF_visual'>
          <geometry>
            <mesh>
              <scale>0.6 0.6 0.6</scale>
              <uri>file:///home/asd/.ignition/fuel/fuel.ignitionrobotics.org/openrobotics/models/depot/6/meshes/Depot.dae</uri>
              <submesh>
                <name>ROOF</name>
                <center>false</center>
              </submesh>
            </mesh>
          </geometry>
          <material>
            <diffuse>1 1 1 1</diffuse>
            <specular>1 1 1 1</specular>
            <pbr>
              <metal>
                <albedo_map>materials/textures/ROOF_Albedo.png</albedo_map>
                <normal_map>materials/textures/ROOF_Normal.png</normal_map>
                <metalness_map>materials/textures/ROOF_Metalness.png</metalness_map>
                <roughness_map>materials/textures/ROOF_Roughness.png</roughness_map>
                <emissive_map>materials/textures/ROOF_Emissive.png</emissive_map>
                <light_map uv_set='1'>materials/textures/DepotLightmap.png</light_map>
              </metal>
            </pbr>
            <script>
              <uri>file:///home/asd/.ignition/fuel/fuel.ignitionrobotics.org/openrobotics/models/depot/6/materials/scripts/</uri>
              <uri>materials/textures/</uri>
              <name>UrbanTile/ROOF_Diffuse</name>
            </script>
          </material>
        </visual>
        <visual name='WALLS_visual'>
          <geometry>
            <mesh>
              <scale>0.6 0.6 0.6</scale>
              <uri>file:///home/asd/.ignition/fuel/fuel.ignitionrobotics.org/openrobotics/models/depot/6/meshes/Depot.dae</uri>
              <submesh>
                <name>WALLS</name>
                <center>false</center>
              </submesh>
            </mesh>
          </geometry>
          <material>
            <diffuse>1 1 1 1</diffuse>
            <specular>1 1 1 1</specular>
            <pbr>
              <metal>
                <albedo_map>materials/textures/WALLS_Albedo.png</albedo_map>
                <normal_map>materials/textures/WALLS_Normal.png</normal_map>
                <metalness_map>materials/textures/WALLS_Metalness.png</metalness_map>
                <roughness_map>materials/textures/WALLS_Roughness.png</roughness_map>
                <light_map uv_set='1'>materials/textures/DepotLightmap.png</light_map>
              </metal>
            </pbr>
            <script>
              <uri>file:///home/asd/.ignition/fuel/fuel.ignitionrobotics.org/openrobotics/models/depot/6/materials/scripts/</uri>
              <uri>materials/textures/</uri>
              <name>UrbanTile/WALLS_Diffuse</name>
            </script>
          </material>
        </visual>
        <visual name='PILLERS_visual'>
          <geometry>
            <mesh>
              <scale>0.6 0.6 0.6</scale>
              <uri>file:///home/asd/.ignition/fuel/fuel.ignitionrobotics.org/openrobotics/models/depot/6/meshes/Depot.dae</uri>
              <submesh>
                <name>PILLERS</name>
                <center>false</center>
              </submesh>
            </mesh>
          </geometry>
          <material>
            <diffuse>1 1 1 1</diffuse>
            <specular>1 1 1 1</specular>
            <pbr>
              <metal>
                <albedo_map>materials/textures/PILLERS_Albedo.png</albedo_map>
                <normal_map>materials/textures/PILLERS_Normal.png</normal_map>
                <metalness_map>materials/textures/PILLERS_Metalness.png</metalness_map>
                <roughness_map>materials/textures/PILLERS_Roughness.png</roughness_map>
                <light_map uv_set='1'>materials/textures/DepotLightmap.png</light_map>
              </metal>
            </pbr>
            <script>
              <uri>file:///home/asd/.ignition/fuel/fuel.ignitionrobotics.org/openrobotics/models/depot/6/materials/scripts/</uri>
              <uri>materials/textures/</uri>
              <name>UrbanTile/PILLERS_Diffuse</name>
            </script>
          </material>
        </visual>
        <visual name='FANS_visual'>
          <geometry>
            <mesh>
              <scale>0.6 0.6 0.6</scale>
              <uri>file:///home/asd/.ignition/fuel/fuel.ignitionrobotics.org/openrobotics/models/depot/6/meshes/Depot.dae</uri>
              <submesh>
                <name>FANS</name>
                <center>false</center>
              </submesh>
            </mesh>
          </geometry>
          <material>
            <diffuse>1 1 1 1</diffuse>
            <specular>1 1 1 1</specular>
            <pbr>
              <metal>
                <albedo_map>materials/textures/FANS_Albedo.png</albedo_map>
                <normal_map>materials/textures/FANS_Normal.png</normal_map>
                <metalness_map>materials/textures/FANS_Metalness.png</metalness_map>
                <roughness_map>materials/textures/FANS_Roughness.png</roughness_map>
                <light_map uv_set='1'>materials/textures/DepotLightmap.png</light_map>
              </metal>
            </pbr>
            <script>
              <uri>file:///home/asd/.ignition/fuel/fuel.ignitionrobotics.org/openrobotics/models/depot/6/materials/scripts/</uri>
              <uri>materials/textures/</uri>
              <name>UrbanTile/FAN_Diffuse</name>
            </script>
          </material>
        </visual>
        <visual name='WINDOW_visual'>
          <geometry>
            <mesh>
              <scale>0.6 0.6 0.6</scale>
              <uri>file:///home/asd/.ignition/fuel/fuel.ignitionrobotics.org/openrobotics/models/depot/6/meshes/Depot.dae</uri>
              <submesh>
                <name>WINDOW</name>
                <center>false</center>
              </submesh>
            </mesh>
          </geometry>
          <material>
            <diffuse>1 1 1 1</diffuse>
            <specular>1 1 1 1</specular>
            <pbr>
              <metal>
                <albedo_map>materials/textures/Window_WINDOW_BaseColor.png</albedo_map>
                <metalness_map>materials/textures/Window_WINDOW_Metallic.png</metalness_map>
                <roughness_map>materials/textures/Window_WINDOW_Roughness.png</roughness_map>
              </metal>
            </pbr>
            <script>
              <uri>file:///home/asd/.ignition/fuel/fuel.ignitionrobotics.org/openrobotics/models/depot/6/materials/scripts/</uri>
              <uri>materials/textures/</uri>
              <name>UrbanTile/WINDOW_Diffuse</name>
            </script>
          </material>
        </visual>
        <visual name='INTERCOM_visual'>
          <geometry>
            <mesh>
              <scale>0.6 0.6 0.6</scale>
              <uri>file:///home/asd/.ignition/fuel/fuel.ignitionrobotics.org/openrobotics/models/depot/6/meshes/Depot.dae</uri>
              <submesh>
                <name>INTERCOM</name>
                <center>false</center>
              </submesh>
            </mesh>
          </geometry>
          <material>
            <diffuse>1 1 1 1</diffuse>
            <specular>1 1 1 1</specular>
            <pbr>
              <metal>
                <albedo_map>materials/textures/INTERCOM_Albedo.png</albedo_map>
                <normal_map>materials/textures/INTERCOM_Normal.png</normal_map>
                <metalness_map>materials/textures/INTERCOM_Metalness.png</metalness_map>
                <roughness_map>materials/textures/INTERCOM_Roughness.png</roughness_map>
                <emissive_map>materials/textures/INTERCOM_Emissive.png</emissive_map>
                <light_map uv_set='1'>materials/textures/DepotLightmap.png</light_map>
              </metal>
            </pbr>
            <script>
              <uri>file:///home/asd/.ignition/fuel/fuel.ignitionrobotics.org/openrobotics/models/depot/6/materials/scripts/</uri>
              <uri>materials/textures/</uri>
              <name>UrbanTile/INTERCOM_Diffuse</name>
            </script>
          </material>
        </visual>
        <visual name='FireAlarm_visual'>
          <geometry>
            <mesh>
              <scale>0.6 0.6 0.6</scale>
              <uri>file:///home/asd/.ignition/fuel/fuel.ignitionrobotics.org/openrobotics/models/depot/6/meshes/Depot.dae</uri>
              <submesh>
                <name>FireAlarm</name>
                <center>false</center>
              </submesh>
            </mesh>
          </geometry>
          <material>
            <diffuse>1 1 1 1</diffuse>
            <specular>1 1 1 1</specular>
            <pbr>
              <metal>
                <albedo_map>materials/textures/FireAlarm_Albedo.png</albedo_map>
                <normal_map>materials/textures/FireAlarm_Normal.png</normal_map>
                <metalness_map>materials/textures/FireAlarm_Metalness.png</metalness_map>
                <roughness_map>materials/textures/FireAlarm_Roughness.png</roughness_map>
                <light_map uv_set='1'>materials/textures/DepotLightmap.png</light_map>
              </metal>
            </pbr>
            <script>
              <uri>file:///home/asd/.ignition/fuel/fuel.ignitionrobotics.org/openrobotics/models/depot/6/materials/scripts/</uri>
              <uri>materials/textures/</uri>
              <name>UrbanTile/FireAlarm_Diffuse</name>
            </script>
          </material>
        </visual>
        <visual name='FireAlarmPole_visual'>
          <geometry>
            <mesh>
              <scale>0.6 0.6 0.6</scale>
              <uri>file:///home/asd/.ignition/fuel/fuel.ignitionrobotics.org/openrobotics/models/depot/6/meshes/Depot.dae</uri>
              <submesh>
                <name>FireAlarmPole</name>
                <center>false</center>
              </submesh>
            </mesh>
          </geometry>
          <material>
            <diffuse>1 1 1 1</diffuse>
            <specular>1 1 1 1</specular>
            <pbr>
              <metal>
                <albedo_map>materials/textures/FireAlarmPole_Albedo.png</albedo_map>
                <normal_map>materials/textures/FireAlarmPole_Normal.png</normal_map>
                <metalness_map>materials/textures/FireAlarmPole_Metalness.png</metalness_map>
                <roughness_map>materials/textures/FireAlarmPole_Roughness.png</roughness_map>
                <light_map uv_set='1'>materials/textures/DepotLightmap.png</light_map>
              </metal>
            </pbr>
            <script>
              <uri>file:///home/asd/.ignition/fuel/fuel.ignitionrobotics.org/openrobotics/models/depot/6/materials/scripts/</uri>
              <uri>materials/textures/</uri>
              <name>UrbanTile/FireAlarmPole</name>
            </script>
          </material>
        </visual>
        <visual name='Pipes_visual'>
          <geometry>
            <mesh>
              <scale>0.6 0.6 0.6</scale>
              <uri>file:///home/asd/.ignition/fuel/fuel.ignitionrobotics.org/openrobotics/models/depot/6/meshes/Depot.dae</uri>
              <submesh>
                <name>Pipes</name>
                <center>false</center>
              </submesh>
            </mesh>
          </geometry>
          <material>
            <diffuse>1 1 1 1</diffuse>
            <specular>1 1 1 1</specular>
            <pbr>
              <metal>
                <albedo_map>materials/textures/Pipes_Albedo.png</albedo_map>
                <normal_map>materials/textures/Pipes_Normal.png</normal_map>
                <metalness_map>materials/textures/Pipes_Metalness.png</metalness_map>
                <roughness_map>materials/textures/Pipes_Roughness.png</roughness_map>
                <light_map uv_set='1'>materials/textures/DepotLightmap.png</light_map>
              </metal>
            </pbr>
            <script>
              <uri>file:///home/asd/.ignition/fuel/fuel.ignitionrobotics.org/openrobotics/models/depot/6/materials/scripts/</uri>
              <uri>materials/textures/</uri>
              <name>UrbanTile/Pipes_Diffuse</name>
            </script>
          </material>
        </visual>
        <visual name='STAIRS_visual'>
          <geometry>
            <mesh>
              <scale>0.6 0.6 0.6</scale>
              <uri>file:///home/asd/.ignition/fuel/fuel.ignitionrobotics.org/openrobotics/models/depot/6/meshes/Depot.dae</uri>
              <submesh>
                <name>STAIRS</name>
                <center>false</center>
              </submesh>
            </mesh>
          </geometry>
          <material>
            <diffuse>1 1 1 1</diffuse>
            <specular>1 1 1 1</specular>
            <pbr>
              <metal>
                <albedo_map>materials/textures/STAIRS_Albedo.png</albedo_map>
                <normal_map>materials/textures/STAIRS_Normal.png</normal_map>
                <metalness_map>materials/textures/STAIRS_Metalness.png</metalness_map>
                <roughness_map>materials/textures/STAIRS_Roughness.png</roughness_map>
                <light_map uv_set='1'>materials/textures/DepotLightmap.png</light_map>
              </metal>
            </pbr>
            <script>
              <uri>file:///home/asd/.ignition/fuel/fuel.ignitionrobotics.org/openrobotics/models/depot/6/materials/scripts/</uri>
              <uri>materials/textures/</uri>
              <name>UrbanTile/STAIRS_Diffuse</name>
            </script>
          </material>
        </visual>
        <visual name='BOXSET_visual'>
          <geometry>
            <mesh>
              <scale>0.6 0.6 0.6</scale>
              <uri>file:///home/asd/.ignition/fuel/fuel.ignitionrobotics.org/openrobotics/models/depot/6/meshes/Depot.dae</uri>
              <submesh>
                <name>BOXSET</name>
                <center>false</center>
              </submesh>
            </mesh>
          </geometry>
          <material>
            <diffuse>1 1 1 1</diffuse>
            <specular>1 1 1 1</specular>
            <pbr>
              <metal>
                <albedo_map>materials/textures/BOXSET_Albedo.png</albedo_map>
                <normal_map>materials/textures/BOXSET_Normal.png</normal_map>
                <metalness_map>materials/textures/BOXSET_Metalness.png</metalness_map>
                <roughness_map>materials/textures/BOXSET_Roughness.png</roughness_map>
                <emissive_map>materials/textures/BOXSET_Emissive.png</emissive_map>
                <light_map uv_set='1'>materials/textures/DepotLightmap.png</light_map>
              </metal>
            </pbr>
            <script>
              <uri>file:///home/asd/.ignition/fuel/fuel.ignitionrobotics.org/openrobotics/models/depot/6/materials/scripts/</uri>
              <uri>materials/textures/</uri>
              <name>UrbanTile/BOXSET_Diffuse</name>
            </script>
          </material>
        </visual>
        <visual name='FLOOR_visual'>
          <geometry>
            <mesh>
              <scale>0.6 0.6 0.6</scale>
              <uri>file:///home/asd/.ignition/fuel/fuel.ignitionrobotics.org/openrobotics/models/depot/6/meshes/Depot.dae</uri>
              <submesh>
                <name>FLOOR</name>
                <center>false</center>
              </submesh>
            </mesh>
          </geometry>
          <material>
            <diffuse>1 1 1 1</diffuse>
            <specular>1 1 1 1</specular>
            <pbr>
              <metal>
                <albedo_map>materials/textures/FLOOR_Albedo.png</albedo_map>
                <normal_map>materials/textures/FLOOR_Normal.png</normal_map>
                <metalness_map>materials/textures/FLOOR_Metalness.png</metalness_map>
                <roughness_map>materials/textures/FLOOR_Roughness.png</roughness_map>
                <light_map uv_set='1'>materials/textures/DepotLightmap.png</light_map>
              </metal>
            </pbr>
            <script>
              <uri>file:///home/asd/.ignition/fuel/fuel.ignitionrobotics.org/openrobotics/models/depot/6/materials/scripts/</uri>
              <uri>materials/textures/</uri>
              <name>UrbanTile/FLOOR_Diffuse</name>
            </script>
          </material>
        </visual>
        <visual name='FanBack_visual'>
          <geometry>
            <mesh>
              <scale>0.6 0.6 0.6</scale>
              <uri>file:///home/asd/.ignition/fuel/fuel.ignitionrobotics.org/openrobotics/models/depot/6/meshes/Depot.dae</uri>
              <submesh>
                <name>FanBack</name>
                <center>false</center>
              </submesh>
            </mesh>
          </geometry>
          <material>
            <diffuse>1 1 1 1</diffuse>
            <specular>1 1 1 1</specular>
            <pbr>
              <metal>
                <albedo_map>materials/textures/FanBack_FanBack_BaseColor.png</albedo_map>
              </metal>
            </pbr>
          </material>
        </visual>
        <visual name='crates'>
          <geometry>
            <mesh>
              <scale>0.6 0.6 0.6</scale>
              <uri>file:///home/asd/.ignition/fuel/fuel.ignitionrobotics.org/openrobotics/models/depot/6/meshes/Crates.dae</uri>
            </mesh>
          </geometry>
          <material>
            <diffuse>1 1 1 1</diffuse>
            <specular>1 1 1 1</specular>
            <pbr>
              <metal>
                <albedo_map>materials/textures/Crates_Crates_BaseColor.png</albedo_map>
                <normal_map>materials/textures/Crates_Crates_Normal.png</normal_map>
                <roughness_map>materials/textures/Crates_Crates_Roughness.png</roughness_map>
              </metal>
            </pbr>
          </material>
        </visual>
        <pose>0 0 0 0 -0 0</pose>
        <inertial>
          <pose>0 0 0 0 -0 0</pose>
          <mass>1</mass>
          <inertia>
            <ixx>1</ixx>
            <ixy>0</ixy>
            <ixz>0</ixz>
            <iyy>1</iyy>
            <iyz>0</iyz>
            <izz>1</izz>
          </inertia>
        </inertial>
        <enable_wind>false</enable_wind>
      </link>
      <link name='Fan1'>
        <pose>-5.0154 -0.2952 6.12 0 -0 0</pose>
        <visual name='visual'>
          <pose>5.0154 0.2952 -6.12 0 0 0</pose>
          <geometry>
            <mesh>
              <scale>0.6 0.6 0.6</scale>
              <uri>file:///home/asd/.ignition/fuel/fuel.ignitionrobotics.org/openrobotics/models/depot/6/meshes/Depot.dae</uri>
              <submesh>
                <name>FAN1</name>
                <center>false</center>
              </submesh>
            </mesh>
          </geometry>
          <material>
            <diffuse>1 1 1 1</diffuse>
            <specular>1 1 1 1</specular>
            <pbr>
              <metal>
                <albedo_map>materials/textures/FANS_Albedo.png</albedo_map>
                <normal_map>materials/textures/FANS_Normal.png</normal_map>
                <metalness_map>materials/textures/FANS_Metalness.png</metalness_map>
                <roughness_map>materials/textures/FANS_Roughness.png</roughness_map>
                <light_map uv_set='1'>materials/textures/DepotLightmap.png</light_map>
              </metal>
            </pbr>
          </material>
        </visual>
        <light name='fan_light' type='point'>
          <pose>0 0 0 0 -0 0</pose>
          <cast_shadows>false</cast_shadows>
          <intensity>1</intensity>
          <direction>0 0 -1</direction>
          <diffuse>1 1 1 1</diffuse>
          <specular>0.3 0.3 0.3 1</specular>
          <attenuation>
            <range>50</range>
            <linear>0</linear>
            <constant>0</constant>
            <quadratic>0</quadratic>
          </attenuation>
          <spot>
            <inner_angle>0</inner_angle>
            <outer_angle>0</outer_angle>
            <falloff>0</falloff>
          </spot>
        </light>
        <inertial>
          <pose>0 0 0 0 -0 0</pose>
          <mass>1</mass>
          <inertia>
            <ixx>1</ixx>
            <ixy>0</ixy>
            <ixz>0</ixz>
            <iyy>1</iyy>
            <iyz>0</iyz>
            <izz>1</izz>
          </inertia>
        </inertial>
        <enable_wind>false</enable_wind>
      </link>
      <link name='Fan2'>
        <pose>5.0154 -0.2952 6.12 0 -0 0</pose>
        <visual name='visual'>
          <pose>5.0154 0.2952 -6.12 0 0 0</pose>
          <geometry>
            <mesh>
              <scale>0.6 0.6 0.6</scale>
              <uri>file:///home/asd/.ignition/fuel/fuel.ignitionrobotics.org/openrobotics/models/depot/6/meshes/Depot.dae</uri>
              <submesh>
                <name>FAN1</name>
                <center>false</center>
              </submesh>
            </mesh>
          </geometry>
          <material>
            <diffuse>1 1 1 1</diffuse>
            <specular>1 1 1 1</specular>
            <pbr>
              <metal>
                <albedo_map>materials/textures/FANS_Albedo.png</albedo_map>
                <normal_map>materials/textures/FANS_Normal.png</normal_map>
                <metalness_map>materials/textures/FANS_Metalness.png</metalness_map>
                <roughness_map>materials/textures/FANS_Roughness.png</roughness_map>
                <light_map uv_set='1'>materials/textures/DepotLightmap.png</light_map>
              </metal>
            </pbr>
          </material>
        </visual>
        <light name='fan_light' type='point'>
          <pose>0 0 0 0 -0 0</pose>
          <cast_shadows>false</cast_shadows>
          <intensity>1</intensity>
          <direction>0 0 -1</direction>
          <diffuse>1 1 1 1</diffuse>
          <specular>0.3 0.3 0.3 1</specular>
          <attenuation>
            <range>50</range>
            <linear>0</linear>
            <constant>0</constant>
            <quadratic>0</quadratic>
          </attenuation>
          <spot>
            <inner_angle>0</inner_angle>
            <outer_angle>0</outer_angle>
            <falloff>0</falloff>
          </spot>
        </light>
        <inertial>
          <pose>0 0 0 0 -0 0</pose>
          <mass>1</mass>
          <inertia>
            <ixx>1</ixx>
            <ixy>0</ixy>
            <ixz>0</ixz>
            <iyy>1</iyy>
            <iyz>0</iyz>
            <izz>1</izz>
          </inertia>
        </inertial>
        <enable_wind>false</enable_wind>
      </link>
      <joint name='world_joint' type='fixed'>
        <parent>world</parent>
        <child>main</child>
        <pose>0 0 0 0 -0 0</pose>
      </joint>
      <joint name='fan1_joint' type='revolute'>
        <parent>main</parent>
        <child>Fan1</child>
        <axis>
          <xyz>0 0 1</xyz>
          <limit>
            <lower>-10000000000000000</lower>
            <upper>10000000000000000</upper>
            <effort>inf</effort>
            <velocity>inf</velocity>
            <stiffness>100000000</stiffness>
            <dissipation>1</dissipation>
          </limit>
          <dynamics>
            <spring_reference>0</spring_reference>
            <spring_stiffness>0</spring_stiffness>
            <damping>0</damping>
            <friction>0</friction>
          </dynamics>
        </axis>
        <pose>0 0 0 0 -0 0</pose>
      </joint>
      <joint name='fan2_joint' type='revolute'>
        <parent>main</parent>
        <child>Fan2</child>
        <axis>
          <xyz>0 0 1</xyz>
          <limit>
            <lower>-10000000000000000</lower>
            <upper>10000000000000000</upper>
            <effort>inf</effort>
            <velocity>inf</velocity>
            <stiffness>100000000</stiffness>
            <dissipation>1</dissipation>
          </limit>
          <dynamics>
            <spring_reference>0</spring_reference>
            <spring_stiffness>0</spring_stiffness>
            <damping>0</damping>
            <friction>0</friction>
          </dynamics>
        </axis>
        <pose>0 0 0 0 -0 0</pose>
      </joint>
      <plugin name='ignition::gazebo::systems::JointController' filename='ignition-gazebo-joint-controller-system'>
        <joint_name>fan1_joint</joint_name>
        <initial_velocity>1.0</initial_velocity>
      </plugin>
      <plugin name='ignition::gazebo::systems::JointController' filename='ignition-gazebo-joint-controller-system'>
        <joint_name>fan2_joint</joint_name>
        <initial_velocity>2.0</initial_velocity>
      </plugin>
      <pose>7.19009 1.09982 0 0 -0 0</pose>
      <self_collide>false</self_collide>
    </model>
    <model name='depot_collision'>
      <static>true</static>
      <pose>7.19009 1.09982 0 0 -0 0</pose>
      <link name='collision_link'>
        <pose>0 0 0 0 -0 0</pose>
        <collision name='wall1'>
          <pose>0 -7.6129 4.5 0 0 0</pose>
          <geometry>
            <box>
              <size>30.167 0.08 9</size>
            </box>
          </geometry>
          <surface>
            <friction>
              <ode/>
            </friction>
            <bounce/>
            <contact/>
          </surface>
        </collision>
        <collision name='wall2'>
          <pose>0 7.2875 4.5 0 0 0</pose>
          <geometry>
            <box>
              <size>30.167 0.08 9</size>
            </box>
          </geometry>
          <surface>
            <friction>
              <ode/>
            </friction>
            <bounce/>
            <contact/>
          </surface>
        </collision>
        <collision name='wall3'>
          <pose>-15 0 4.5 0 0 0</pose>
          <geometry>
            <box>
              <size>0.08 15.36 9</size>
            </box>
          </geometry>
          <surface>
            <friction>
              <ode/>
            </friction>
            <bounce/>
            <contact/>
          </surface>
        </collision>
        <collision name='wall4'>
          <pose>15 0 4.5 0 0 0</pose>
          <geometry>
            <box>
              <size>0.08 15.36 9</size>
            </box>
          </geometry>
          <surface>
            <friction>
              <ode/>
            </friction>
            <bounce/>
            <contact/>
          </surface>
        </collision>
        <collision name='boxes1'>
          <pose>0.22268 -4.7268 0.68506 0 0 0</pose>
          <geometry>
            <box>
              <size>1.288 1.422 1.288</size>
            </box>
          </geometry>
          <surface>
            <friction>
              <ode/>
            </friction>
            <bounce/>
            <contact/>
          </surface>
        </collision>
        <collision name='boxes2'>
          <pose>3.1727 -4.7268 0.68506 0 0 0</pose>
          <geometry>
            <box>
              <size>1.288 1.422 1.288</size>
            </box>
          </geometry>
          <surface>
            <friction>
              <ode/>
            </friction>
            <bounce/>
            <contact/>
          </surface>
        </collision>
        <collision name='boxes3'>
          <pose>5.95268 -4.7268 0.68506 0 0 0</pose>
          <geometry>
            <box>
              <size>1.288 1.422 1.288</size>
            </box>
          </geometry>
          <surface>
            <friction>
              <ode/>
            </friction>
            <bounce/>
            <contact/>
          </surface>
        </collision>
        <collision name='boxes4'>
          <pose>8.55887 -4.7268 0.68506 0 0 0</pose>
          <geometry>
            <box>
              <size>1.288 1.422 1.288</size>
            </box>
          </geometry>
          <surface>
            <friction>
              <ode/>
            </friction>
            <bounce/>
            <contact/>
          </surface>
        </collision>
        <collision name='boxes5'>
          <pose>11.326 -4.7268 0.68506 0 0 0</pose>
          <geometry>
            <box>
              <size>1.288 1.422 1.288</size>
            </box>
          </geometry>
          <surface>
            <friction>
              <ode/>
            </friction>
            <bounce/>
            <contact/>
          </surface>
        </collision>
        <collision name='boxes6'>
          <pose>0.22268 -2.37448 0.68506 0 0 0</pose>
          <geometry>
            <box>
              <size>1.288 1.422 1.288</size>
            </box>
          </geometry>
          <surface>
            <friction>
              <ode/>
            </friction>
            <bounce/>
            <contact/>
          </surface>
        </collision>
        <collision name='boxes7'>
          <pose>3.1727 -2.37448 0.68506 0 0 0</pose>
          <geometry>
            <box>
              <size>1.288 1.422 1.288</size>
            </box>
          </geometry>
          <surface>
            <friction>
              <ode/>
            </friction>
            <bounce/>
            <contact/>
          </surface>
        </collision>
        <collision name='boxes8'>
          <pose>5.95268 -2.37448 0.68506 0 0 0</pose>
          <geometry>
            <box>
              <size>1.288 1.422 1.288</size>
            </box>
          </geometry>
          <surface>
            <friction>
              <ode/>
            </friction>
            <bounce/>
            <contact/>
          </surface>
        </collision>
        <collision name='boxes9'>
          <pose>8.55887 -2.37448 0.68506 0 0 0</pose>
          <geometry>
            <box>
              <size>1.288 1.422 1.288</size>
            </box>
          </geometry>
          <surface>
            <friction>
              <ode/>
            </friction>
            <bounce/>
            <contact/>
          </surface>
        </collision>
        <collision name='boxes10'>
          <pose>11.326 -2.37448 0.68506 0 0 0</pose>
          <geometry>
            <box>
              <size>1.288 1.422 1.288</size>
            </box>
          </geometry>
          <surface>
            <friction>
              <ode/>
            </friction>
            <bounce/>
            <contact/>
          </surface>
        </collision>
        <collision name='boxes11'>
          <pose>-1.2268 4.1557 0.68506 0 0 -1.02799893</pose>
          <geometry>
            <box>
              <size>1.288 1.422 1.288</size>
            </box>
          </geometry>
          <surface>
            <friction>
              <ode/>
            </friction>
            <bounce/>
            <contact/>
          </surface>
        </collision>
        <collision name='pilar1'>
          <pose>-7.5402 3.6151 1 0 0 0</pose>
          <geometry>
            <box>
              <size>0.465 0.465 2</size>
            </box>
          </geometry>
          <surface>
            <friction>
              <ode/>
            </friction>
            <bounce/>
            <contact/>
          </surface>
        </collision>
        <collision name='pilar2'>
          <pose>7.4575 3.6151 1 0 0 0</pose>
          <geometry>
            <box>
              <size>0.465 0.465 2</size>
            </box>
          </geometry>
          <surface>
            <friction>
              <ode/>
            </friction>
            <bounce/>
            <contact/>
          </surface>
        </collision>
        <collision name='pilar3'>
          <pose>-7.5402 -3.8857 1 0 0 0</pose>
          <geometry>
            <box>
              <size>0.465 0.465 2</size>
            </box>
          </geometry>
          <surface>
            <friction>
              <ode/>
            </friction>
            <bounce/>
            <contact/>
          </surface>
        </collision>
        <collision name='pilar4'>
          <pose>7.4575 -3.8857 1 0 0 0</pose>
          <geometry>
            <box>
              <size>0.465 0.465 2</size>
            </box>
          </geometry>
          <surface>
            <friction>
              <ode/>
            </friction>
            <bounce/>
            <contact/>
          </surface>
        </collision>
        <collision name='pallet_mover1'>
          <pose>-0.6144 -2.389 0.41838 0 0 0</pose>
          <geometry>
            <box>
              <size>0.363 0.44 0.719</size>
            </box>
          </geometry>
          <surface>
            <friction>
              <ode/>
            </friction>
            <bounce/>
            <contact/>
          </surface>
        </collision>
        <collision name='pallet_mover2'>
          <pose>-1.6004 4.8225 0.41838 0 0 0</pose>
          <geometry>
            <box>
              <size>0.363 0.244 0.719</size>
            </box>
          </geometry>
          <surface>
            <friction>
              <ode/>
            </friction>
            <bounce/>
            <contact/>
          </surface>
        </collision>
        <collision name='stairs'>
          <pose>13.018 3.1652 0.25 0 0 0</pose>
          <geometry>
            <box>
              <size>1.299 0.6 0.5</size>
            </box>
          </geometry>
          <surface>
            <friction>
              <ode/>
            </friction>
            <bounce/>
            <contact/>
          </surface>
        </collision>
        <collision name='shelfs1'>
          <pose>1.4662 -0.017559 0.5 0 0 0</pose>
          <geometry>
            <cylinder>
              <radius>0.029999999999999999</radius>
              <length>1</length>
            </cylinder>
          </geometry>
          <surface>
            <friction>
              <ode/>
            </friction>
            <bounce/>
            <contact/>
          </surface>
        </collision>
        <collision name='shelfs2'>
          <pose>2.6483 -0.017559 0.5 0 0 0</pose>
          <geometry>
            <cylinder>
              <radius>0.029999999999999999</radius>
              <length>1</length>
            </cylinder>
          </geometry>
          <surface>
            <friction>
              <ode/>
            </friction>
            <bounce/>
            <contact/>
          </surface>
        </collision>
        <collision name='shelfs3'>
          <pose>5.3247 -0.017559 0.5 0 0 0</pose>
          <geometry>
            <cylinder>
              <radius>0.029999999999999999</radius>
              <length>1</length>
            </cylinder>
          </geometry>
          <surface>
            <friction>
              <ode/>
            </friction>
            <bounce/>
            <contact/>
          </surface>
        </collision>
        <collision name='shelfs4'>
          <pose>6.5063 -0.017559 0.5 0 0 0</pose>
          <geometry>
            <cylinder>
              <radius>0.029999999999999999</radius>
              <length>1</length>
            </cylinder>
          </geometry>
          <surface>
            <friction>
              <ode/>
            </friction>
            <bounce/>
            <contact/>
          </surface>
        </collision>
        <collision name='shelfs5'>
          <pose>9.0758 -0.017559 0.5 0 0 0</pose>
          <geometry>
            <cylinder>
              <radius>0.029999999999999999</radius>
              <length>1</length>
            </cylinder>
          </geometry>
          <surface>
            <friction>
              <ode/>
            </friction>
            <bounce/>
            <contact/>
          </surface>
        </collision>
        <collision name='shelfs6'>
          <pose>10.258 -0.017559 0.5 0 0 0</pose>
          <geometry>
            <cylinder>
              <radius>0.029999999999999999</radius>
              <length>1</length>
            </cylinder>
          </geometry>
          <surface>
            <friction>
              <ode/>
            </friction>
            <bounce/>
            <contact/>
          </surface>
        </collision>
        <collision name='shelfs7'>
          <pose>1.4662 2.5664 0.5 0 0 0</pose>
          <geometry>
            <cylinder>
              <radius>0.029999999999999999</radius>
              <length>1</length>
            </cylinder>
          </geometry>
          <surface>
            <friction>
              <ode/>
            </friction>
            <bounce/>
            <contact/>
          </surface>
        </collision>
        <collision name='shelfs8'>
          <pose>2.6483 2.5664 0.5 0 0 0</pose>
          <geometry>
            <cylinder>
              <radius>0.029999999999999999</radius>
              <length>1</length>
            </cylinder>
          </geometry>
          <surface>
            <friction>
              <ode/>
            </friction>
            <bounce/>
            <contact/>
          </surface>
        </collision>
        <collision name='shelfs9'>
          <pose>5.3247 2.5664 0.5 0 0 0</pose>
          <geometry>
            <cylinder>
              <radius>0.029999999999999999</radius>
              <length>1</length>
            </cylinder>
          </geometry>
          <surface>
            <friction>
              <ode/>
            </friction>
            <bounce/>
            <contact/>
          </surface>
        </collision>
        <collision name='shelfs10'>
          <pose>6.5063 2.5664 0.5 0 0 0</pose>
          <geometry>
            <cylinder>
              <radius>0.029999999999999999</radius>
              <length>1</length>
            </cylinder>
          </geometry>
          <surface>
            <friction>
              <ode/>
            </friction>
            <bounce/>
            <contact/>
          </surface>
        </collision>
        <collision name='shelfs11'>
          <pose>9.0758 2.5664 0.5 0 0 0</pose>
          <geometry>
            <cylinder>
              <radius>0.029999999999999999</radius>
              <length>1</length>
            </cylinder>
          </geometry>
          <surface>
            <friction>
              <ode/>
            </friction>
            <bounce/>
            <contact/>
          </surface>
        </collision>
        <collision name='shelfs12'>
          <pose>10.258 2.5664 0.5 0 0 0</pose>
          <geometry>
            <cylinder>
              <radius>0.029999999999999999</radius>
              <length>1</length>
            </cylinder>
          </geometry>
          <surface>
            <friction>
              <ode/>
            </friction>
            <bounce/>
            <contact/>
          </surface>
        </collision>
        <collision name='shelfs13'>
          <pose>1.4662 5.1497 0.5 0 0 0</pose>
          <geometry>
            <cylinder>
              <radius>0.029999999999999999</radius>
              <length>1</length>
            </cylinder>
          </geometry>
          <surface>
            <friction>
              <ode/>
            </friction>
            <bounce/>
            <contact/>
          </surface>
        </collision>
        <collision name='shelfs14'>
          <pose>2.6483 5.1497 0.5 0 0 0</pose>
          <geometry>
            <cylinder>
              <radius>0.029999999999999999</radius>
              <length>1</length>
            </cylinder>
          </geometry>
          <surface>
            <friction>
              <ode/>
            </friction>
            <bounce/>
            <contact/>
          </surface>
        </collision>
        <collision name='shelfs15'>
          <pose>5.3247 5.1497 0.5 0 0 0</pose>
          <geometry>
            <cylinder>
              <radius>0.029999999999999999</radius>
              <length>1</length>
            </cylinder>
          </geometry>
          <surface>
            <friction>
              <ode/>
            </friction>
            <bounce/>
            <contact/>
          </surface>
        </collision>
        <collision name='shelfs16'>
          <pose>6.5063 5.1497 0.5 0 0 0</pose>
          <geometry>
            <cylinder>
              <radius>0.029999999999999999</radius>
              <length>1</length>
            </cylinder>
          </geometry>
          <surface>
            <friction>
              <ode/>
            </friction>
            <bounce/>
            <contact/>
          </surface>
        </collision>
        <collision name='shelfs17'>
          <pose>9.0758 5.1497 0.5 0 0 0</pose>
          <geometry>
            <cylinder>
              <radius>0.029999999999999999</radius>
              <length>1</length>
            </cylinder>
          </geometry>
          <surface>
            <friction>
              <ode/>
            </friction>
            <bounce/>
            <contact/>
          </surface>
        </collision>
        <collision name='shelfs18'>
          <pose>10.258 5.1497 0.5 0 0 0</pose>
          <geometry>
            <cylinder>
              <radius>0.029999999999999999</radius>
              <length>1</length>
            </cylinder>
          </geometry>
          <surface>
            <friction>
              <ode/>
            </friction>
            <bounce/>
            <contact/>
          </surface>
        </collision>
        <inertial>
          <pose>0 0 0 0 -0 0</pose>
          <mass>1</mass>
          <inertia>
            <ixx>1</ixx>
            <ixy>0</ixy>
            <ixz>0</ixz>
            <iyy>1</iyy>
            <iyz>0</iyz>
            <izz>1</izz>
          </inertia>
        </inertial>
        <enable_wind>false</enable_wind>
      </link>
      <self_collide>false</self_collide>
    </model>
    <model name='tugbot'>
      <self_collide>false</self_collide>
      <pose>1.9975 -0.413735 0.132279 0 -0 0</pose>
      <static>false</static>
      <link name='base_link'>
        <pose>0 0 0 0 -0 0</pose>
        <inertial>
          <pose>-0.1 0 0.1 0 -0 0</pose>
          <mass>46.200000000000003</mass>
          <inertia>
            <ixx>1.55925</ixx>
            <ixy>0</ixy>
            <ixz>0</ixz>
            <iyy>1.55925</iyy>
            <iyz>0</iyz>
            <izz>1.55925</izz>
          </inertia>
        </inertial>
        <collision name='base_link_collision'>
          <pose>0 0 0 0 0 0</pose>
          <geometry>
            <mesh>
              <uri>file:///home/asd/.ignition/fuel/fuel.ignitionrobotics.org/movai/models/tugbot/1/meshes/base/tugbot_simp.stl</uri>
            </mesh>
          </geometry>
        </collision>
        <visual name='base_link_visual'>
          <pose>0 0 0 0 0 0</pose>
          <geometry>
            <mesh>
              <uri>file:///home/asd/.ignition/fuel/fuel.ignitionrobotics.org/movai/models/tugbot/1/meshes/base/tugbot_simp.dae</uri>
            </mesh>
          </geometry>
        </visual>
        <visual name='movai_logo_visual'>
          <pose>0 0 0 0 0 0</pose>
          <geometry>
            <mesh>
              <uri>file:///home/asd/.ignition/fuel/fuel.ignitionrobotics.org/movai/models/tugbot/1/meshes/base/movai_logo.dae</uri>
            </mesh>
          </geometry>
          <material>
            <diffuse>1 1 1 1</diffuse>
            <pbr>
              <metal>
                <albedo_map>meshes/base/movai-logo.png</albedo_map>
              </metal>
            </pbr>
          </material>
        </visual>
        <visual name='light_link_visual'>
          <pose>-0.1 0 0.1945 0 1.57079632679 0</pose>
          <geometry>
            <mesh>
              <scale>1 1 1</scale>
              <uri>file:///home/asd/.ignition/fuel/fuel.ignitionrobotics.org/movai/models/tugbot/1/meshes/light_link/light_led.stl</uri>
            </mesh>
          </geometry>
          <material>
            <ambient>0 0 0 1</ambient>
            <diffuse>0 0 0 1</diffuse>
            <specular>0 0 0 1</specular>
            <emissive>0 1 0 1</emissive>
          </material>
        </visual>
        <visual name='warnign_light_visual'>
          <pose>-0.099 0 0.195 0 1.57079632679 0</pose>
          <geometry>
            <mesh>
              <scale>1.02 1.02 1.02</scale>
              <uri>file:///home/asd/.ignition/fuel/fuel.ignitionrobotics.org/movai/models/tugbot/1/meshes/light_link/light.stl</uri>
            </mesh>
          </geometry>
          <material>
            <ambient>0.1 0.05 0 0.5</ambient>
            <diffuse>1 0.5 0 0.5</diffuse>
            <specular>1 0.5 0 0.5</specular>
            <emissive>1 0.5 0 0.5</emissive>
          </material>
        </visual>
        <enable_wind>false</enable_wind>
      </link>
      <link name='imu_link'>
        <pose>0.14 0.02 0.25 0 0 -1.57</pose>
        <sensor name='imu' type='imu'>
          <pose>0 0 0 0 -0 0</pose>
          <topic>__default__</topic>
          <update_rate>30</update_rate>
          <enable_metrics>false</enable_metrics>
          <imu>
            <orientation_reference_frame>
              <localization>CUSTOM</localization>
              <custom_rpy>0 0 0</custom_rpy>
              <grav_dir_x>1 0 0</grav_dir_x>
            </orientation_reference_frame>
            <angular_velocity>
              <x>
                <noise type='none'>
                  <mean>0</mean>
                  <stddev>0</stddev>
                  <bias_mean>0</bias_mean>
                  <bias_stddev>0</bias_stddev>
                  <dynamic_bias_stddev>0</dynamic_bias_stddev>
                  <dynamic_bias_correlation_time>0</dynamic_bias_correlation_time>
                  <precision>0</precision>
                </noise>
              </x>
              <y>
                <noise type='none'>
                  <mean>0</mean>
                  <stddev>0</stddev>
                  <bias_mean>0</bias_mean>
                  <bias_stddev>0</bias_stddev>
                  <dynamic_bias_stddev>0</dynamic_bias_stddev>
                  <dynamic_bias_correlation_time>0</dynamic_bias_correlation_time>
                  <precision>0</precision>
                </noise>
              </y>
              <z>
                <noise type='none'>
                  <mean>0</mean>
                  <stddev>0</stddev>
                  <bias_mean>0</bias_mean>
                  <bias_stddev>0</bias_stddev>
                  <dynamic_bias_stddev>0</dynamic_bias_stddev>
                  <dynamic_bias_correlation_time>0</dynamic_bias_correlation_time>
                  <precision>0</precision>
                </noise>
              </z>
            </angular_velocity>
            <linear_acceleration>
              <x>
                <noise type='none'>
                  <mean>0</mean>
                  <stddev>0</stddev>
                  <bias_mean>0</bias_mean>
                  <bias_stddev>0</bias_stddev>
                  <dynamic_bias_stddev>0</dynamic_bias_stddev>
                  <dynamic_bias_correlation_time>0</dynamic_bias_correlation_time>
                  <precision>0</precision>
                </noise>
              </x>
              <y>
                <noise type='none'>
                  <mean>0</mean>
                  <stddev>0</stddev>
                  <bias_mean>0</bias_mean>
                  <bias_stddev>0</bias_stddev>
                  <dynamic_bias_stddev>0</dynamic_bias_stddev>
                  <dynamic_bias_correlation_time>0</dynamic_bias_correlation_time>
                  <precision>0</precision>
                </noise>
              </y>
              <z>
                <noise type='none'>
                  <mean>0</mean>
                  <stddev>0</stddev>
                  <bias_mean>0</bias_mean>
                  <bias_stddev>0</bias_stddev>
                  <dynamic_bias_stddev>0</dynamic_bias_stddev>
                  <dynamic_bias_correlation_time>0</dynamic_bias_correlation_time>
                  <precision>0</precision>
                </noise>
              </z>
            </linear_acceleration>
            <enable_orientation>true</enable_orientation>
          </imu>
        </sensor>
        <inertial>
          <pose>0 0 0 0 -0 0</pose>
          <mass>1</mass>
          <inertia>
            <ixx>1</ixx>
            <ixy>0</ixy>
            <ixz>0</ixz>
            <iyy>1</iyy>
            <iyz>0</iyz>
            <izz>1</izz>
          </inertia>
        </inertial>
        <enable_wind>false</enable_wind>
      </link>
      <joint name='imu_link_joint' type='fixed'>
        <child>imu_link</child>
        <parent>base_link</parent>
        <pose>0 0 0 0 -0 0</pose>
      </joint>
      <link name='warnign_light'>
        <pose>-0.185 0 0.46 0 -0 0</pose>
        <inertial>
          <pose>0 0 0 0 -0 0</pose>
          <mass>0.10000000000000001</mass>
          <inertia>
            <ixx>1.6875e-05</ixx>
            <ixy>0</ixy>
            <ixz>0</ixz>
            <iyy>1e-08</iyy>
            <iyz>0</iyz>
            <izz>1.6875e-05</izz>
          </inertia>
        </inertial>
        <light name='warnign_light_lamp' type='spot'>
          <pose>-0.04 0 0 0 1.5708 0</pose>
          <cast_shadows>true</cast_shadows>
          <intensity>1</intensity>
          <direction>0 0 -1</direction>
          <diffuse>1 0.5 0 1</diffuse>
          <specular>1 0.5 0 1</specular>
          <attenuation>
            <range>5</range>
            <linear>0</linear>
            <constant>0.10000000000000001</constant>
            <quadratic>0.0025000000000000001</quadratic>
          </attenuation>
          <spot>
            <inner_angle>0.90000000000000002</inner_angle>
            <outer_angle>1</outer_angle>
            <falloff>2</falloff>
          </spot>
        </light>
        <enable_wind>false</enable_wind>
      </link>
      <joint name='warnign_light_joint' type='revolute'>
        <child>warnign_light</child>
        <parent>base_link</parent>
        <axis>
          <xyz>0 0 1</xyz>
          <limit>
            <lower>-10000000000000000</lower>
            <upper>10000000000000000</upper>
            <effort>1000</effort>
            <velocity>20</velocity>
            <stiffness>100000000</stiffness>
            <dissipation>1</dissipation>
          </limit>
          <dynamics>
            <spring_reference>0</spring_reference>
            <spring_stiffness>0</spring_stiffness>
            <damping>0</damping>
            <friction>0</friction>
          </dynamics>
        </axis>
        <pose>0 0 0 0 -0 0</pose>
      </joint>
      <link name='camera_front'>
        <pose>0.0553 0 0.4323 0 -0 0</pose>
        <sensor name='color' type='camera'>
          <pose>0 0.0325 0.0125 0 -0 0</pose>
          <topic>__default__</topic>
          <update_rate>6</update_rate>
          <enable_metrics>false</enable_metrics>
          <camera name='__default__'>
            <pose>0 0 0 0 -0 0</pose>
            <horizontal_fov>1.20428</horizontal_fov>
            <image>
              <width>848</width>
              <height>480</height>
              <format>RGB_INT8</format>
              <anti_aliasing>4</anti_aliasing>
            </image>
            <camera_info_topic>__default__</camera_info_topic>
            <trigger_topic></trigger_topic>
            <triggered>false</triggered>
            <clip>
              <near>0.10000000000000001</near>
              <far>50</far>
            </clip>
            <save enabled='false'>
              <path>__default__</path>
            </save>
            <visibility_mask>4294967295</visibility_mask>
            <noise>
              <type>none</type>
              <mean>0</mean>
              <stddev>0</stddev>
            </noise>
            <distortion>
              <k1>0</k1>
              <k2>0</k2>
              <k3>0</k3>
              <p1>0</p1>
              <p2>0</p2>
              <center>0.5 0.5</center>
            </distortion>
            <lens>
              <type>stereographic</type>
              <scale_to_hfov>true</scale_to_hfov>
              <cutoff_angle>1.5707</cutoff_angle>
              <env_texture_size>256</env_texture_size>
              <intrinsics>
                <fx>615.96000000000004</fx>
                <fy>616.22699999999998</fy>
                <cx>419.82999999999998</cx>
                <cy>245.143</cy>
                <s>0</s>
              </intrinsics>
            </lens>
            <optical_frame_id></optical_frame_id>
          </camera>
        </sensor>
        <sensor name='depth' type='depth_camera'>
          <pose>0 0.0175 0.0125 0 -0 0</pose>
          <topic>__default__</topic>
          <update_rate>6</update_rate>
          <enable_metrics>false</enable_metrics>
          <camera name='__default__'>
            <pose>0 0 0 0 -0 0</pose>
            <horizontal_fov>1.51844</horizontal_fov>
            <image>
              <width>848</width>
              <height>480</height>
              <format>R_FLOAT32</format>
              <anti_aliasing>4</anti_aliasing>
            </image>
            <camera_info_topic>__default__</camera_info_topic>
            <trigger_topic></trigger_topic>
            <triggered>false</triggered>
            <clip>
              <near>0.10000000000000001</near>
              <far>10</far>
            </clip>
            <save enabled='false'>
              <path>__default__</path>
            </save>
            <visibility_mask>4294967295</visibility_mask>
            <noise>
              <type>none</type>
              <mean>0</mean>
              <stddev>0</stddev>
            </noise>
            <distortion>
              <k1>0</k1>
              <k2>0</k2>
              <k3>0</k3>
              <p1>0</p1>
              <p2>0</p2>
              <center>0.5 0.5</center>
            </distortion>
            <lens>
              <type>stereographic</type>
              <scale_to_hfov>true</scale_to_hfov>
              <cutoff_angle>1.5707</cutoff_angle>
              <env_texture_size>256</env_texture_size>
              <intrinsics>
                <fx>421.61599999999999</fx>
                <fy>421.61599999999999</fy>
                <cx>422.28500000000003</cx>
                <cy>236.572</cy>
                <s>0</s>
              </intrinsics>
            </lens>
            <optical_frame_id></optical_frame_id>
          </camera>
        </sensor>
        <inertial>
          <pose>0 0 0 0 -0 0</pose>
          <mass>1</mass>
          <inertia>
            <ixx>1</ixx>
            <ixy>0</ixy>
            <ixz>0</ixz>
            <iyy>1</iyy>
            <iyz>0</iyz>
            <izz>1</izz>
          </inertia>
        </inertial>
        <enable_wind>false</enable_wind>
      </link>
      <joint name='camera_front_joint' type='fixed'>
        <child>camera_front</child>
        <parent>base_link</parent>
        <pose>0 0 0 0 -0 0</pose>
      </joint>
      <link name='camera_back'>
        <pose>-0.241 0 0.2303 0 -0 -3.14159</pose>
        <sensor name='color' type='camera'>
          <pose>0 0.0325 0.0125 0 -0 0</pose>
          <topic>__default__</topic>
          <update_rate>6</update_rate>
          <enable_metrics>false</enable_metrics>
          <camera name='__default__'>
            <pose>0 0 0 0 -0 0</pose>
            <horizontal_fov>1.20428</horizontal_fov>
            <image>
              <width>848</width>
              <height>480</height>
              <format>RGB_INT8</format>
              <anti_aliasing>4</anti_aliasing>
            </image>
            <camera_info_topic>__default__</camera_info_topic>
            <trigger_topic></trigger_topic>
            <triggered>false</triggered>
            <clip>
              <near>0.10000000000000001</near>
              <far>50</far>
            </clip>
            <save enabled='false'>
              <path>__default__</path>
            </save>
            <visibility_mask>4294967295</visibility_mask>
            <noise>
              <type>none</type>
              <mean>0</mean>
              <stddev>0</stddev>
            </noise>
            <distortion>
              <k1>0</k1>
              <k2>0</k2>
              <k3>0</k3>
              <p1>0</p1>
              <p2>0</p2>
              <center>0.5 0.5</center>
            </distortion>
            <lens>
              <type>stereographic</type>
              <scale_to_hfov>true</scale_to_hfov>
              <cutoff_angle>1.5707</cutoff_angle>
              <env_texture_size>256</env_texture_size>
              <intrinsics>
                <fx>615.96000000000004</fx>
                <fy>616.22699999999998</fy>
                <cx>419.82999999999998</cx>
                <cy>245.143</cy>
                <s>0</s>
              </intrinsics>
            </lens>
            <optical_frame_id></optical_frame_id>
          </camera>
        </sensor>
        <sensor name='depth' type='depth_camera'>
          <pose>0 0.0175 0.0125 0 -0 0</pose>
          <topic>__default__</topic>
          <update_rate>6</update_rate>
          <enable_metrics>false</enable_metrics>
          <camera name='__default__'>
            <pose>0 0 0 0 -0 0</pose>
            <horizontal_fov>1.51844</horizontal_fov>
            <image>
              <width>848</width>
              <height>480</height>
              <format>R_FLOAT32</format>
              <anti_aliasing>4</anti_aliasing>
            </image>
            <camera_info_topic>__default__</camera_info_topic>
            <trigger_topic></trigger_topic>
            <triggered>false</triggered>
            <clip>
              <near>0.10000000000000001</near>
              <far>10</far>
            </clip>
            <save enabled='false'>
              <path>__default__</path>
            </save>
            <visibility_mask>4294967295</visibility_mask>
            <noise>
              <type>none</type>
              <mean>0</mean>
              <stddev>0</stddev>
            </noise>
            <distortion>
              <k1>0</k1>
              <k2>0</k2>
              <k3>0</k3>
              <p1>0</p1>
              <p2>0</p2>
              <center>0.5 0.5</center>
            </distortion>
            <lens>
              <type>stereographic</type>
              <scale_to_hfov>true</scale_to_hfov>
              <cutoff_angle>1.5707</cutoff_angle>
              <env_texture_size>256</env_texture_size>
              <intrinsics>
                <fx>421.61599999999999</fx>
                <fy>421.61599999999999</fy>
                <cx>422.28500000000003</cx>
                <cy>236.572</cy>
                <s>0</s>
              </intrinsics>
            </lens>
            <optical_frame_id></optical_frame_id>
          </camera>
        </sensor>
        <inertial>
          <pose>0 0 0 0 -0 0</pose>
          <mass>1</mass>
          <inertia>
            <ixx>1</ixx>
            <ixy>0</ixy>
            <ixz>0</ixz>
            <iyy>1</iyy>
            <iyz>0</iyz>
            <izz>1</izz>
          </inertia>
        </inertial>
        <enable_wind>false</enable_wind>
      </link>
      <joint name='camera_back_joint' type='fixed'>
        <child>camera_back</child>
        <parent>base_link</parent>
        <pose>0 0 0 0 -0 0</pose>
      </joint>
      <link name='scan_front'>
        <pose>0.221 0 0.1404 0 -0 0</pose>
        <sensor name='scan_front' type='gpu_lidar'>
          <pose>0 0 0 0 -0 0</pose>
          <topic>__default__</topic>
          <update_rate>10</update_rate>
          <enable_metrics>false</enable_metrics>
          <lidar>
            <scan>
              <horizontal>
                <samples>674</samples>
                <resolution>1</resolution>
                <min_angle>-1.47044</min_angle>
                <max_angle>1.47044</max_angle>
              </horizontal>
              <vertical>
                <samples>1</samples>
                <min_angle>0</min_angle>
                <max_angle>0</max_angle>
                <resolution>1</resolution>
              </vertical>
            </scan>
            <range>
              <min>0.01</min>
              <max>5</max>
              <resolution>0.01</resolution>
            </range>
            <noise>
              <type>none</type>
              <mean>0</mean>
              <stddev>0</stddev>
            </noise>
            <visibility_mask>4294967295</visibility_mask>
          </lidar>
        </sensor>
        <inertial>
          <pose>0 0 0 0 -0 0</pose>
          <mass>1</mass>
          <inertia>
            <ixx>1</ixx>
            <ixy>0</ixy>
            <ixz>0</ixz>
            <iyy>1</iyy>
            <iyz>0</iyz>
            <izz>1</izz>
          </inertia>
        </inertial>
        <enable_wind>false</enable_wind>
      </link>
      <joint name='scan_front_joint' type='fixed'>
        <child>scan_front</child>
        <parent>base_link</parent>
        <pose>0 0 0 0 -0 0</pose>
      </joint>
      <link name='scan_back'>
        <pose>-0.2075 0 0.205 0 -0 -3.14159</pose>
        <sensor name='scan_back' type='gpu_lidar'>
          <pose>0 0 0 0 -0 0</pose>
          <topic>__default__</topic>
          <update_rate>5</update_rate>
          <enable_metrics>false</enable_metrics>
          <lidar>
            <scan>
              <horizontal>
                <samples>480</samples>
                <resolution>1</resolution>
                <min_angle>-1.47044</min_angle>
                <max_angle>1.47044</max_angle>
              </horizontal>
              <vertical>
                <samples>1</samples>
                <min_angle>0</min_angle>
                <max_angle>0</max_angle>
                <resolution>1</resolution>
              </vertical>
            </scan>
            <range>
              <min>0.01</min>
              <max>5</max>
              <resolution>0.01</resolution>
            </range>
            <noise>
              <type>none</type>
              <mean>0</mean>
              <stddev>0</stddev>
            </noise>
            <visibility_mask>4294967295</visibility_mask>
          </lidar>
        </sensor>
        <inertial>
          <pose>0 0 0 0 -0 0</pose>
          <mass>1</mass>
          <inertia>
            <ixx>1</ixx>
            <ixy>0</ixy>
            <ixz>0</ixz>
            <iyy>1</iyy>
            <iyz>0</iyz>
            <izz>1</izz>
          </inertia>
        </inertial>
        <enable_wind>false</enable_wind>
      </link>
      <joint name='scan_back_joint' type='fixed'>
        <child>scan_back</child>
        <parent>base_link</parent>
        <pose>0 0 0 0 -0 0</pose>
      </joint>
      <link name='scan_omni'>
        <pose>-0.1855 0 0.5318 0 -0 0</pose>
        <visual name='velodyne_base'>
          <pose>0 0 -0.035 0 0 0</pose>
          <geometry>
            <cylinder>
              <radius>0.059999999999999998</radius>
              <length>0.0015</length>
            </cylinder>
          </geometry>
        </visual>
        <visual name='velodyne_suport_1'>
          <pose>-0.035 0.035 -0.08 0 0 0</pose>
          <geometry>
            <cylinder>
              <radius>0.0050000000000000001</radius>
              <length>0.089999999999999997</length>
            </cylinder>
          </geometry>
        </visual>
        <visual name='velodyne_suport_2'>
          <pose>-0.035 -0.035 -0.08 0 0 0</pose>
          <geometry>
            <cylinder>
              <radius>0.0050000000000000001</radius>
              <length>0.089999999999999997</length>
            </cylinder>
          </geometry>
        </visual>
        <visual name='velodyne_suport_3'>
          <pose>0.0495 0 -0.08 0 0 0</pose>
          <geometry>
            <cylinder>
              <radius>0.0050000000000000001</radius>
              <length>0.089999999999999997</length>
            </cylinder>
          </geometry>
        </visual>
        <visual name='velodyne_base_link_visual_base'>
          <pose>0 0 -0.035 0 0 0</pose>
          <geometry>
            <mesh>
              <scale>1 1 1</scale>
              <uri>file:///home/asd/.ignition/fuel/fuel.ignitionrobotics.org/movai/models/tugbot/1/meshes/VLP16_base_1.dae</uri>
            </mesh>
          </geometry>
        </visual>
        <visual name='velodyne_base_link_visual_sensor'>
          <pose>0 0 -0.035 0 0 0</pose>
          <geometry>
            <mesh>
              <scale>1 1 1</scale>
              <uri>file:///home/asd/.ignition/fuel/fuel.ignitionrobotics.org/movai/models/tugbot/1/meshes/VLP16_base_2.dae</uri>
            </mesh>
          </geometry>
        </visual>
        <visual name='base_link_velodyne_visual_scan'>
          <pose>0 0 -0.035 0 0 0</pose>
          <geometry>
            <mesh>
              <scale>1 1 1</scale>
              <uri>file:///home/asd/.ignition/fuel/fuel.ignitionrobotics.org/movai/models/tugbot/1/meshes/VLP16_scan.dae</uri>
            </mesh>
          </geometry>
        </visual>
        <sensor name='scan_omni' type='gpu_lidar'>
          <pose>0 0 0 0 -0 0</pose>
          <topic>__default__</topic>
          <update_rate>10</update_rate>
          <enable_metrics>false</enable_metrics>
          <lidar>
            <scan>
              <horizontal>
                <samples>900</samples>
                <resolution>1</resolution>
                <min_angle>-3.1415899999999999</min_angle>
                <max_angle>3.1415899999999999</max_angle>
              </horizontal>
              <vertical>
                <samples>16</samples>
                <min_angle>-0.261799</min_angle>
                <max_angle>0.261799</max_angle>
                <resolution>1</resolution>
              </vertical>
            </scan>
            <range>
              <min>0.20000000000000001</min>
              <max>100</max>
              <resolution>0.01</resolution>
            </range>
            <noise>
              <type>none</type>
              <mean>0</mean>
              <stddev>0</stddev>
            </noise>
            <visibility_mask>4294967295</visibility_mask>
          </lidar>
        </sensor>
        <inertial>
          <pose>0 0 0 0 -0 0</pose>
          <mass>1</mass>
          <inertia>
            <ixx>1</ixx>
            <ixy>0</ixy>
            <ixz>0</ixz>
            <iyy>1</iyy>
            <iyz>0</iyz>
            <izz>1</izz>
          </inertia>
        </inertial>
        <enable_wind>false</enable_wind>
      </link>
      <joint name='scan_omni_joint' type='fixed'>
        <child>scan_omni</child>
        <parent>base_link</parent>
        <pose>0 0 0 0 -0 0</pose>
      </joint>
      <link name='gripper'>
        <pose>-0.35 0 0.1 0 -0 0</pose>
        <inertial>
          <pose>0 0 0 0 -0 0</pose>
          <mass>1</mass>
          <inertia>
            <ixx>0.0016666700000000001</ixx>
            <ixy>0</ixy>
            <ixz>0</ixz>
            <iyy>0.0016666700000000001</iyy>
            <iyz>0</iyz>
            <izz>0.0016666700000000001</izz>
          </inertia>
        </inertial>
        <collision name='gripper_collision'>
          <pose>-0.005 0 0 0 -0 0</pose>
          <max_contacts>5</max_contacts>
          <geometry>
            <box>
              <size>0.15 0.1 0.1</size>
            </box>
          </geometry>
          <surface>
            <contact>
              <ode>
                <kp>1000000</kp>
                <kd>1</kd>
                <min_depth>0.01</min_depth>
                <max_vel>1</max_vel>
              </ode>
            </contact>
            <friction>
              <ode>
                <mu>1.1599999999999999</mu>
                <mu2>1.1599999999999999</mu2>
              </ode>
            </friction>
            <bounce/>
          </surface>
        </collision>
        <visual name='gripper_visual'>
          <pose>0 0 0 -1.57079632679 0 0</pose>
          <geometry>
            <mesh>
              <scale>1 1 1</scale>
              <uri>file:///home/asd/.ignition/fuel/fuel.ignitionrobotics.org/movai/models/tugbot/1/meshes/gripper2/gripper2.dae</uri>
            </mesh>
          </geometry>
        </visual>
        <sensor name='sensor_contact' type='gpu_lidar'>
          <pose>-0.075 0 0.035 0 -0 -3.14159</pose>
          <topic>__default__</topic>
          <update_rate>10</update_rate>
          <enable_metrics>false</enable_metrics>
          <lidar>
            <scan>
              <horizontal>
                <samples>3</samples>
                <resolution>1</resolution>
                <min_angle>-0.02</min_angle>
                <max_angle>0.02</max_angle>
              </horizontal>
              <vertical>
                <samples>1</samples>
                <min_angle>0</min_angle>
                <max_angle>0</max_angle>
                <resolution>1</resolution>
              </vertical>
            </scan>
            <range>
              <min>0.001</min>
              <max>0.01</max>
              <resolution>0.001</resolution>
            </range>
            <noise>
              <type>none</type>
              <mean>0</mean>
              <stddev>0</stddev>
            </noise>
            <visibility_mask>4294967295</visibility_mask>
          </lidar>
        </sensor>
        <enable_wind>false</enable_wind>
      </link>
      <joint name='gripper_joint' type='revolute'>
        <pose>0.35 0 0.09 0 -0 0</pose>
        <child>gripper</child>
        <parent>base_link</parent>
        <axis>
          <xyz>0 0 1</xyz>
          <limit>
            <lower>-0.69999999999999996</lower>
            <upper>0.69999999999999996</upper>
            <effort>4</effort>
            <velocity>0.5</velocity>
            <stiffness>100000000</stiffness>
            <dissipation>1</dissipation>
          </limit>
          <dynamics>
            <spring_reference>0</spring_reference>
            <spring_stiffness>0</spring_stiffness>
            <damping>0</damping>
            <friction>0.5</friction>
          </dynamics>
        </axis>
      </joint>
      <link name='gripper_hand'>
        <pose>-0.463 0 0.1 0 -0 0</pose>
        <inertial>
          <pose>0 0 0 0 -0 0</pose>
          <mass>0.20000000000000001</mass>
          <inertia>
            <ixx>1.5999999999999999e-05</ixx>
            <ixy>0</ixy>
            <ixz>0</ixz>
            <iyy>1.5999999999999999e-05</iyy>
            <iyz>0</iyz>
            <izz>1.5999999999999999e-05</izz>
          </inertia>
        </inertial>
        <collision name='gripper_hand_collision'>
          <pose>0.015 0 0.006 0 0 0</pose>
          <geometry>
            <box>
              <size>0.04 0.1 0.017</size>
            </box>
          </geometry>
          <max_contacts>5</max_contacts>
          <surface>
            <contact>
              <ode>
                <kp>1000000</kp>
                <kd>1</kd>
                <min_depth>0.01</min_depth>
                <max_vel>1</max_vel>
              </ode>
            </contact>
            <friction>
              <ode>
                <mu>1.1599999999999999</mu>
                <mu2>1.1599999999999999</mu2>
              </ode>
            </friction>
            <bounce/>
          </surface>
        </collision>
        <visual name='gripper_hand_visual'>
          <pose>0 0 0 1.570796327 0 1.570796327</pose>
          <geometry>
            <mesh>
              <scale>0.001 0.001 0.001</scale>
              <uri>file:///home/asd/.ignition/fuel/fuel.ignitionrobotics.org/movai/models/tugbot/1/meshes/gripper2/gripper_hand.stl</uri>
            </mesh>
          </geometry>
          <material>
            <ambient>0.1 0.1 0.1 1</ambient>
            <diffuse>0.3 0.3 0.3 1</diffuse>
            <specular>1 1 1 1</specular>
            <emissive>0 0 0 1</emissive>
          </material>
        </visual>
        <collision name='gripper_hand_sideL_collision'>
          <pose>0 0.08 0.03 0 0 0</pose>
          <geometry>
            <box>
              <size>0.01 0.05 0.07</size>
            </box>
          </geometry>
          <surface>
            <contact>
              <ode>
                <kp>1000000</kp>
                <kd>1</kd>
                <min_depth>0.01</min_depth>
                <max_vel>1</max_vel>
              </ode>
            </contact>
            <friction>
              <ode>
                <mu>1.1599999999999999</mu>
                <mu2>1.1599999999999999</mu2>
              </ode>
            </friction>
            <bounce/>
          </surface>
        </collision>
        <collision name='gripper_hand_sideL_slide_collision'>
          <pose>0 0.055 0.03 0.9 0 0</pose>
          <geometry>
            <box>
              <size>0.01 0.055 0.04</size>
            </box>
          </geometry>
          <surface>
            <contact>
              <ode>
                <kp>1000000</kp>
                <kd>1</kd>
                <min_depth>0.01</min_depth>
                <max_vel>1</max_vel>
              </ode>
            </contact>
            <friction>
              <ode>
                <mu>0</mu>
                <mu2>0</mu2>
              </ode>
            </friction>
            <bounce/>
          </surface>
        </collision>
        <collision name='gripper_hand_sideR_collision'>
          <pose>0 -0.08 0.03 0 0 0</pose>
          <geometry>
            <box>
              <size>0.01 0.05 0.07</size>
            </box>
          </geometry>
          <surface>
            <contact>
              <ode>
                <kp>1000000</kp>
                <kd>1</kd>
                <min_depth>0.01</min_depth>
                <max_vel>1</max_vel>
              </ode>
            </contact>
            <friction>
              <ode>
                <mu>1.1599999999999999</mu>
                <mu2>1.1599999999999999</mu2>
              </ode>
            </friction>
            <bounce/>
          </surface>
        </collision>
        <collision name='gripper_hand_sideR_slide_collision'>
          <pose>0 -0.055 0.03 -0.9 0 0</pose>
          <geometry>
            <box>
              <size>0.01 0.055 0.04</size>
            </box>
          </geometry>
          <surface>
            <contact>
              <ode>
                <kp>1000000</kp>
                <kd>1</kd>
                <min_depth>0.01</min_depth>
                <max_vel>1</max_vel>
              </ode>
            </contact>
            <friction>
              <ode>
                <mu>0</mu>
                <mu2>0</mu2>
              </ode>
            </friction>
            <bounce/>
          </surface>
        </collision>
        <enable_wind>false</enable_wind>
      </link>
      <joint name='gripper_hand_joint' type='revolute'>
        <pose>0.2 0 0 0 -0 0</pose>
        <child>gripper_hand</child>
        <parent>gripper</parent>
        <axis>
          <xyz>0 1 0</xyz>
          <limit>
            <lower>-0.34999999999999998</lower>
            <upper>0.10000000000000001</upper>
            <effort>100</effort>
            <velocity>0.5</velocity>
            <stiffness>100000000</stiffness>
            <dissipation>1</dissipation>
          </limit>
          <dynamics>
            <spring_reference>0</spring_reference>
            <spring_stiffness>0</spring_stiffness>
            <damping>0</damping>
            <friction>0</friction>
          </dynamics>
        </axis>
      </joint>
      <link name='wheel_front'>
        <pose>0.145 0 0.0345 1.5708 -0 0</pose>
        <inertial>
          <pose>0 0 0 0 -0 0</pose>
          <mass>0.10000000000000001</mass>
          <inertia>
            <ixx>1.7499999999999998e-05</ixx>
            <ixy>0</ixy>
            <ixz>0</ixz>
            <iyy>1.7499999999999998e-05</iyy>
            <iyz>0</iyz>
            <izz>1.7499999999999998e-05</izz>
          </inertia>
        </inertial>
        <collision name='wheel_front_collision'>
          <pose>0 0 0 0 0 0</pose>
          <geometry>
            <sphere>
              <radius>0.025000000000000001</radius>
            </sphere>
          </geometry>
          <max_contacts>2</max_contacts>
          <surface>
            <contact>
              <ode>
                <kp>1000000</kp>
                <kd>1</kd>
                <min_depth>0.01</min_depth>
                <max_vel>1</max_vel>
              </ode>
            </contact>
            <friction>
              <ode>
                <mu>1.1599999999999999</mu>
                <mu2>1.1599999999999999</mu2>
              </ode>
            </friction>
            <bounce/>
          </surface>
        </collision>
        <enable_wind>false</enable_wind>
      </link>
      <joint name='wheel_front_joint' type='ball'>
        <child>wheel_front</child>
        <parent>base_link</parent>
        <axis>
          <xyz>0 0 1</xyz>
          <limit>
            <lower>-10000000000000000</lower>
            <upper>10000000000000000</upper>
            <effort>100</effort>
            <velocity>inf</velocity>
            <stiffness>100000000</stiffness>
            <dissipation>1</dissipation>
          </limit>
          <dynamics>
            <spring_reference>0</spring_reference>
            <spring_stiffness>0</spring_stiffness>
            <damping>10</damping>
            <friction>0</friction>
          </dynamics>
        </axis>
        <pose>0 0 0 0 -0 0</pose>
      </joint>
      <link name='wheel_back'>
        <pose>-0.225 0 0.035 1.5708 -0 0</pose>
        <inertial>
          <pose>0 0 0 0 -0 0</pose>
          <mass>0.10000000000000001</mass>
          <inertia>
            <ixx>1.7499999999999998e-05</ixx>
            <ixy>0</ixy>
            <ixz>0</ixz>
            <iyy>1.7499999999999998e-05</iyy>
            <iyz>0</iyz>
            <izz>1.7499999999999998e-05</izz>
          </inertia>
        </inertial>
        <collision name='wheel_back_collision'>
          <pose>0 0 0 0 0 0</pose>
          <geometry>
            <sphere>
              <radius>0.035000000000000003</radius>
            </sphere>
          </geometry>
          <max_contacts>2</max_contacts>
          <surface>
            <contact>
              <ode>
                <kp>1000000</kp>
                <kd>1</kd>
                <min_depth>0.01</min_depth>
                <max_vel>1</max_vel>
              </ode>
            </contact>
            <friction>
              <ode>
                <mu>1.1599999999999999</mu>
                <mu2>1.1599999999999999</mu2>
              </ode>
            </friction>
            <bounce/>
          </surface>
        </collision>
        <enable_wind>false</enable_wind>
      </link>
      <joint name='wheel_back_joint' type='ball'>
        <child>wheel_back</child>
        <parent>base_link</parent>
        <axis>
          <xyz>0 0 1</xyz>
          <limit>
            <lower>-10000000000000000</lower>
            <upper>10000000000000000</upper>
            <effort>100</effort>
            <velocity>inf</velocity>
            <stiffness>100000000</stiffness>
            <dissipation>1</dissipation>
          </limit>
          <dynamics>
            <spring_reference>0</spring_reference>
            <spring_stiffness>0</spring_stiffness>
            <damping>10</damping>
            <friction>0</friction>
          </dynamics>
        </axis>
        <pose>0 0 -0 0 -0 0</pose>
      </joint>
      <link name='wheel_left'>
        <pose>0 0.257 0.195 -1.5708 0 0</pose>
        <inertial>
          <pose>0 0 0 0 -0 0</pose>
          <mass>0.10000000000000001</mass>
          <inertia>
            <ixx>1.7499999999999998e-05</ixx>
            <ixy>0</ixy>
            <ixz>0</ixz>
            <iyy>1.7499999999999998e-05</iyy>
            <iyz>0</iyz>
            <izz>3.1250000000000001e-05</izz>
          </inertia>
        </inertial>
        <collision name='wheel_left_collision'>
          <pose>0 0 0 0 0 0</pose>
          <geometry>
            <cylinder>
              <radius>0.19500000000000001</radius>
              <length>0.050000000000000003</length>
            </cylinder>
          </geometry>
          <max_contacts>5</max_contacts>
          <surface>
            <contact>
              <ode>
                <kp>1000000</kp>
                <kd>1</kd>
                <min_depth>0.01</min_depth>
                <max_vel>1</max_vel>
              </ode>
            </contact>
            <friction>
              <ode>
                <mu>1.1599999999999999</mu>
                <mu2>10</mu2>
                <fdir1>1 0 0</fdir1>
              </ode>
            </friction>
            <bounce/>
          </surface>
        </collision>
        <visual name='wheel_left_visual'>
          <pose>0 0 -0.03 0 0 0</pose>
          <geometry>
            <mesh>
              <scale>0.98 0.98 1</scale>
              <uri>file:///home/asd/.ignition/fuel/fuel.ignitionrobotics.org/movai/models/tugbot/1/meshes/wheel/wheel.dae</uri>
            </mesh>
          </geometry>
        </visual>
        <enable_wind>false</enable_wind>
      </link>
      <joint name='wheel_left_joint' type='revolute'>
        <child>wheel_left</child>
        <parent>base_link</parent>
        <axis>
          <xyz>0 0 1</xyz>
          <limit>
            <lower>-10000000000000000</lower>
            <upper>10000000000000000</upper>
            <effort>9.5999999999999996</effort>
            <velocity>inf</velocity>
            <stiffness>100000000</stiffness>
            <dissipation>1</dissipation>
          </limit>
          <dynamics>
            <spring_reference>0</spring_reference>
            <spring_stiffness>0</spring_stiffness>
            <damping>3</damping>
            <friction>0.5</friction>
          </dynamics>
        </axis>
        <pose>0 0 0 0 -0 0</pose>
      </joint>
      <link name='wheel_right'>
        <pose>0 -0.257 0.195 1.5708 -0 0</pose>
        <inertial>
          <pose>0 0 0 0 -0 0</pose>
          <mass>0.10000000000000001</mass>
          <inertia>
            <ixx>1.7499999999999998e-05</ixx>
            <ixy>0</ixy>
            <ixz>0</ixz>
            <iyy>1.7499999999999998e-05</iyy>
            <iyz>0</iyz>
            <izz>3.1250000000000001e-05</izz>
          </inertia>
        </inertial>
        <collision name='wheel_right_collision'>
          <pose>0 0 0 0 0 0</pose>
          <geometry>
            <cylinder>
              <radius>0.19500000000000001</radius>
              <length>0.050000000000000003</length>
            </cylinder>
          </geometry>
          <max_contacts>5</max_contacts>
          <surface>
            <contact>
              <ode>
                <kp>1000000</kp>
                <kd>1</kd>
                <min_depth>0.01</min_depth>
                <max_vel>1</max_vel>
              </ode>
            </contact>
            <friction>
              <ode>
                <mu>1.1599999999999999</mu>
                <mu2>10</mu2>
                <fdir1>1 0 0</fdir1>
              </ode>
            </friction>
            <bounce/>
          </surface>
        </collision>
        <visual name='wheel_right_visual'>
          <pose>0 0 -0.03 0 0 0</pose>
          <geometry>
            <mesh>
              <scale>0.98 0.98 1</scale>
              <uri>file:///home/asd/.ignition/fuel/fuel.ignitionrobotics.org/movai/models/tugbot/1/meshes/wheel/wheel.dae</uri>
            </mesh>
          </geometry>
        </visual>
        <enable_wind>false</enable_wind>
      </link>
      <joint name='wheel_right_joint' type='revolute'>
        <child>wheel_right</child>
        <parent>base_link</parent>
        <axis>
          <xyz>0 0 -1</xyz>
          <limit>
            <lower>-10000000000000000</lower>
            <upper>10000000000000000</upper>
            <effort>9.5999999999999996</effort>
            <velocity>inf</velocity>
            <stiffness>100000000</stiffness>
            <dissipation>1</dissipation>
          </limit>
          <dynamics>
            <spring_reference>0</spring_reference>
            <spring_stiffness>0</spring_stiffness>
            <damping>3</damping>
            <friction>0.5</friction>
          </dynamics>
        </axis>
        <pose>0 0 0 0 -0 0</pose>
      </joint>
      <plugin name='ignition::gazebo::systems::DiffDrive' filename='ignition-gazebo-diff-drive-system'>
        <left_joint>wheel_left_joint</left_joint>
        <right_joint>wheel_right_joint</right_joint>
        <wheel_separation>0.5605</wheel_separation>
        <wheel_radius>0.195</wheel_radius>
        <odom_publish_frequency>20</odom_publish_frequency>
        <frame_id>odom</frame_id>
        <child_frame_id>base_link</child_frame_id>
      </plugin>
      <plugin name='ignition::gazebo::systems::JointController' filename='ignition-gazebo-joint-controller-system'>
        <joint_name>gripper_joint</joint_name>
        <use_force_commands>true</use_force_commands>
        <p_gain>0.2</p_gain>
        <i_gain>0.01</i_gain>
      </plugin>
      <plugin name='ignition::gazebo::systems::JointController' filename='ignition-gazebo-joint-controller-system'>
        <joint_name>gripper_hand_joint</joint_name>
        <use_force_commands>true</use_force_commands>
        <p_gain>0.2</p_gain>
        <i_gain>0.01</i_gain>
      </plugin>
      <plugin name='ignition::gazebo::systems::PosePublisher' filename='ignition-gazebo-pose-publisher-system'>
        <publish_link_pose>true</publish_link_pose>
        <publish_collision_pose>false</publish_collision_pose>
        <publish_visual_pose>false</publish_visual_pose>
        <publish_sensor_pose>false</publish_sensor_pose>
        <publish_nested_model_pose>true</publish_nested_model_pose>
        <update_frequency>20</update_frequency>
      </plugin>
      <plugin name='ignition::gazebo::systems::JointController' filename='ignition-gazebo-joint-controller-system'>
        <joint_name>warnign_light_joint</joint_name>
        <initial_velocity>10.0</initial_velocity>
      </plugin>
      <plugin name='ignition::gazebo::systems::LinearBatteryPlugin' filename='ignition-gazebo-linearbatteryplugin-system'>
        <battery_name>linear_battery</battery_name>
        <voltage>24.592</voltage>
        <open_circuit_voltage_constant_coef>24.592</open_circuit_voltage_constant_coef>
        <capacity>1.2009</capacity>
        <power_load>6.5</power_load>
        <fix_issue_225>true</fix_issue_225>
        <enable_recharge>true</enable_recharge>
        <charging_time>3.0</charging_time>
        <recharge_by_topic>true</recharge_by_topic>
      </plugin>
      <plugin name='ignition::gazebo::systems::JointStatePublisher' filename='ignition-gazebo-joint-state-publisher-system'>
        <joint_name>gripper_joint</joint_name>
        <joint_name>gripper_hand_joint</joint_name>
      </plugin>
    </model>
  </world>
</sdf>
